<?xml version="1.0" encoding="utf-8"?>
<!-- This URDF was automatically created by SolidWorks to URDF Exporter! Originally created by Stephen Brawner (brawner@gmail.com) 
     Commit Version: 1.5.1-0-g916b5db  Build Version: 1.5.7152.31018
     For more information, please see http://wiki.ros.org/sw_urdf_exporter -->
<robot
  name="cw2">
  <link
    name="Base">
    <inertial>
      <origin
        xyz="-0.0103440198515111 0.00278990141042701 0.307992605321708"
        rpy="0 0 0" />
      <mass
        value="5.26325366509137" />
      <inertia
        ixx="0.0219350627580291"
        ixy="-4.01751561824983E-06"
        ixz="-1.47975198134269E-06"
        iyy="0.0231941861217009"
        iyz="-8.31653282119486E-06"
        izz="0.0148943720049105" />
    </inertial>
    <visual>
      <origin
        xyz="0 0 0"
        rpy="0 0 0" />
      <geometry>
        <mesh
          filename="package://cw2/meshes/Base.STL" />
      </geometry>
      <material
        name="">
        <color
          rgba="0.752941176470588 0.752941176470588 0.752941176470588 1" />
      </material>
    </visual>
    <collision>
      <origin
        xyz="0 0 0"
        rpy="0 0 0" />
      <geometry>
        <mesh
          filename="package://cw2/meshes/Base.STL" />
      </geometry>
    </collision>
  </link>
  <link
    name="LFS">
    <inertial>
      <origin
        xyz="0.0666875210853818 0.00364278355332764 -0.0648369138582873"
        rpy="0 0 0" />
      <mass
        value="0.26437001106024" />
      <inertia
        ixx="3.20746276473134E-05"
        ixy="-1.44118283521323E-07"
        ixz="-6.30853084344804E-08"
        iyy="6.22704126338856E-05"
        iyz="-2.01894652764193E-07"
        izz="6.28519936954001E-05" />
    </inertial>
    <visual>
      <origin
        xyz="0 0 0"
        rpy="0 0 0" />
      <geometry>
        <mesh
          filename="package://cw2/meshes/LFS.STL" />
      </geometry>
      <material
        name="">
        <color
          rgba="0.752941176470588 0.752941176470588 0.752941176470588 1" />
      </material>
    </visual>
    <collision>
      <origin
        xyz="0 0 0"
        rpy="0 0 0" />
      <geometry>
        <mesh
          filename="package://cw2/meshes/LFS.STL" />
      </geometry>
    </collision>
  </link>
  <joint
    name="LFS"
    type="prismatic">
    <origin
      xyz="0.195921511885521 -0.400832554820273 -0.125694167771293"
      rpy="2.8339623757072 0 3.14159265358979" />
    <parent
      link="Base" />
    <child
      link="LFS" />
    <axis
      xyz="0 0.30280101609128 -0.953053799454201" />
    <limit
      lower="0"
      upper="0"
      effort="0"
      velocity="0" />
  </joint>
  <link
    name="LFW">
    <inertial>
      <origin
        xyz="-0.012315724574073 -1.38777878078145E-17 0"
        rpy="0 0 0" />
      <mass
        value="0.193585420779862" />
      <inertia
        ixx="0.000253081141332254"
        ixy="-5.88092833198904E-37"
        ixz="5.1845054750851E-21"
        iyy="0.000136818598566517"
        iyz="7.17557753438369E-37"
        izz="0.000136818598566517" />
    </inertial>
    <visual>
      <origin
        xyz="0 0 0"
        rpy="0 0 0" />
      <geometry>
        <mesh
          filename="package://cw2/meshes/LFW.STL" />
      </geometry>
      <material
        name="">
        <color
          rgba="1 1 1 1" />
      </material>
    </visual>
    <collision>
      <origin
        xyz="0 0 0"
        rpy="0 0 0" />
      <geometry>
        <mesh
          filename="package://cw2/meshes/LFW.STL" />
      </geometry>
    </collision>
  </link>
  <joint
    name="LFW"
    type="continuous">
    <origin
      xyz="0.000410991135076699 -0.0182187173367753 -0.0397861154043609"
      rpy="-1.87842660467749 0 3.14159265358979" />
    <parent
      link="LFS" />
    <child
      link="LFW" />
    <axis
      xyz="1 0 0" />
  </joint>
  <link
    name="RFS">
    <inertial>
      <origin
        xyz="0.0724473276378504 -0.00242306558271338 -0.0667549990091164"
        rpy="0 0 0" />
      <mass
        value="0.26437001106024" />
      <inertia
        ixx="3.20746276473134E-05"
        ixy="1.4411828352133E-07"
        ixz="6.30853084344787E-08"
        iyy="6.22704126338856E-05"
        iyz="-2.01894652764193E-07"
        izz="6.28519936954002E-05" />
    </inertial>
    <visual>
      <origin
        xyz="0 0 0"
        rpy="0 0 0" />
      <geometry>
        <mesh
          filename="package://cw2/meshes/RFS.STL" />
      </geometry>
      <material
        name="">
        <color
          rgba="0.752941176470588 0.752941176470588 0.752941176470588 1" />
      </material>
    </visual>
    <collision>
      <origin
        xyz="0 0 0"
        rpy="0 0 0" />
      <geometry>
        <mesh
          filename="package://cw2/meshes/RFS.STL" />
      </geometry>
    </collision>
  </link>
  <joint
    name="RFS"
    type="prismatic">
    <origin
      xyz="-0.224160276937101 -0.439516262899762 -0.125694167771293"
      rpy="2.8339623757072 0 0" />
    <parent
      link="Base" />
    <child
      link="RFS" />
    <axis
      xyz="0 0.30280101609128 -0.953053799454201" />
    <limit
      lower="0"
      upper="0"
      effort="0"
      velocity="0" />
  </joint>
  <link
    name="RFW">
    <inertial>
      <origin
        xyz="-0.012315724574073 0 0"
        rpy="0 0 0" />
      <mass
        value="0.193585420779862" />
      <inertia
        ixx="0.000253081141332254"
        ixy="-9.44297928840748E-22"
        ixz="9.68305644339428E-21"
        iyy="0.000136818598566517"
        iyz="1.01643953670516E-20"
        izz="0.000136818598566517" />
    </inertial>
    <visual>
      <origin
        xyz="0 0 0"
        rpy="0 0 0" />
      <geometry>
        <mesh
          filename="package://cw2/meshes/RFW.STL" />
      </geometry>
      <material
        name="">
        <color
          rgba="1 1 1 1" />
      </material>
    </visual>
    <collision>
      <origin
        xyz="0 0 0"
        rpy="0 0 0" />
      <geometry>
        <mesh
          filename="package://cw2/meshes/RFW.STL" />
      </geometry>
    </collision>
  </link>
  <joint
    name="RFW"
    type="continuous">
    <origin
      xyz="0.00617079768754525 0.000974051196125147 -0.0336899045278703"
      rpy="-0.699426690072099 0 3.14159265358979" />
    <parent
      link="RFS" />
    <child
      link="RFW" />
    <axis
      xyz="1 0 0" />
  </joint>
  <link
    name="LBS">
    <inertial>
      <origin
        xyz="0.0754022136877307 -0.00953574862501649 -0.0222014198592475"
        rpy="0 0 0" />
      <mass
        value="0.197009126147877" />
      <inertia
        ixx="1.68802738687172E-05"
        ixy="2.58362469530557E-21"
        ixz="1.18520819431776E-21"
        iyy="5.02184885667569E-05"
        iyz="1.05088759291849E-06"
        izz="4.72447473350486E-05" />
    </inertial>
    <visual>
      <origin
        xyz="0 0 0"
        rpy="0 0 0" />
      <geometry>
        <mesh
          filename="package://cw2/meshes/LBS.STL" />
      </geometry>
      <material
        name="">
        <color
          rgba="0.752941176470588 0.752941176470588 0.752941176470588 1" />
      </material>
    </visual>
    <collision>
      <origin
        xyz="0 0 0"
        rpy="0 0 0" />
      <geometry>
        <mesh
          filename="package://cw2/meshes/LBS.STL" />
      </geometry>
    </collision>
  </link>
  <joint
    name="LBS"
    type="prismatic">
    <origin
      xyz="0.195921511885521 -0.220832554820273 -0.0742634321807595"
      rpy="2.8339623757072 0 3.14159265358979" />
    <parent
      link="Base" />
    <child
      link="LBS" />
    <axis
      xyz="0 0.302801016091279 -0.953053799454201" />
    <limit
      lower="0"
      upper="0"
      effort="0"
      velocity="0" />
  </joint>
  <link
    name="LBC">
    <inertial>
      <origin
        xyz="0.0021267567875245 -0.00125107346378661 -2.77555756156289E-17"
        rpy="0 0 0" />
      <mass
        value="0.0337925918529465" />
      <inertia
        ixx="9.9077845929407E-06"
        ixy="1.2779398016802E-06"
        ixz="4.16196805620863E-22"
        iyy="2.88462343109062E-06"
        iyz="2.46038886416933E-21"
        izz="1.17553584577796E-05" />
    </inertial>
    <visual>
      <origin
        xyz="0 0 0"
        rpy="0 0 0" />
      <geometry>
        <mesh
          filename="package://cw2/meshes/LBC.STL" />
      </geometry>
      <material
        name="">
        <color
          rgba="0.898039215686275 0.917647058823529 0.929411764705882 1" />
      </material>
    </visual>
    <collision>
      <origin
        xyz="0 0 0"
        rpy="0 0 0" />
      <geometry>
        <mesh
          filename="package://cw2/meshes/LBC.STL" />
      </geometry>
    </collision>
  </link>
  <joint
    name="LBC"
    type="continuous">
    <origin
      xyz="0.0411609911350767 -0.0150684419408276 -0.00478749419309598"
      rpy="-1.87842660467749 0 3.14159265358979" />
    <parent
      link="LBS" />
    <child
      link="LBC" />
    <axis
      xyz="0 1 0" />
  </joint>
  <link
    name="LBW">
    <inertial>
      <origin
        xyz="0.017684275425927 0 0"
        rpy="0 0 0" />
      <mass
        value="0.193585420779862" />
      <inertia
        ixx="0.000253081141332254"
        ixy="-5.88092833198904E-37"
        ixz="5.1845054750851E-21"
        iyy="0.000136818598566517"
        iyz="7.17557753438369E-37"
        izz="0.000136818598566517" />
    </inertial>
    <visual>
      <origin
        xyz="0 0 0"
        rpy="0 0 0" />
      <geometry>
        <mesh
          filename="package://cw2/meshes/LBW.STL" />
      </geometry>
      <material
        name="">
        <color
          rgba="1 1 1 1" />
      </material>
    </visual>
    <collision>
      <origin
        xyz="0 0 0"
        rpy="0 0 0" />
      <geometry>
        <mesh
          filename="package://cw2/meshes/LBW.STL" />
      </geometry>
    </collision>
  </link>
  <joint
    name="LBW"
    type="continuous">
    <origin
      xyz="0.01075 -0.0190326828634146 0"
      rpy="0 0 0" />
    <parent
      link="LBC" />
    <child
      link="LBW" />
    <axis
      xyz="1 0 0" />
  </joint>
  <link
    name="RBS">
    <inertial>
      <origin
        xyz="0.0754022136877307 -0.00953574862501652 -0.0222014198592475"
        rpy="0 0 0" />
      <mass
        value="0.197009126147877" />
      <inertia
        ixx="1.68802738687172E-05"
        ixy="-2.41437922096227E-21"
        ixz="-1.24106156676994E-21"
        iyy="5.02184885667569E-05"
        iyz="1.05088759291849E-06"
        izz="4.72447473350486E-05" />
    </inertial>
    <visual>
      <origin
        xyz="0 0 0"
        rpy="0 0 0" />
      <geometry>
        <mesh
          filename="package://cw2/meshes/RBS.STL" />
      </geometry>
      <material
        name="">
        <color
          rgba="0.752941176470588 0.752941176470588 0.752941176470588 1" />
      </material>
    </visual>
    <collision>
      <origin
        xyz="0 0 0"
        rpy="0 0 0" />
      <geometry>
        <mesh
          filename="package://cw2/meshes/RBS.STL" />
      </geometry>
    </collision>
  </link>
  <joint
    name="RBS"
    type="prismatic">
    <origin
      xyz="-0.218400470384632 -0.252453942719796 -0.0742634321807595"
      rpy="2.8339623757072 0 0" />
    <parent
      link="Base" />
    <child
      link="RBS" />
    <axis
      xyz="0 0.30280101609128 -0.953053799454201" />
    <limit
      lower="0"
      upper="0"
      effort="0"
      velocity="0" />
  </joint>
  <link
    name="RBC">
    <inertial>
      <origin
        xyz="0.00212675678752453 -0.00125107346378658 0"
        rpy="0 0 0" />
      <mass
        value="0.0337925918529465" />
      <inertia
        ixx="9.90778459294068E-06"
        ixy="1.2779398016802E-06"
        ixz="6.79399474451284E-22"
        iyy="2.88462343109061E-06"
        iyz="2.61210532719032E-21"
        izz="1.17553584577795E-05" />
    </inertial>
    <visual>
      <origin
        xyz="0 0 0"
        rpy="0 0 0" />
      <geometry>
        <mesh
          filename="package://cw2/meshes/RBC.STL" />
      </geometry>
      <material
        name="">
        <color
          rgba="0.898039215686275 0.917647058823529 0.929411764705882 1" />
      </material>
    </visual>
    <collision>
      <origin
        xyz="0 0 0"
        rpy="0 0 0" />
      <geometry>
        <mesh
          filename="package://cw2/meshes/RBC.STL" />
      </geometry>
    </collision>
  </link>
  <joint
    name="RBC"
    type="continuous">
    <origin
      xyz="0.0411609911350767 -0.0150684419408277 -0.00478749419309599"
      rpy="-1.87842660467749 0 3.14159265358979" />
    <parent
      link="RBS" />
    <child
      link="RBC" />
    <axis
      xyz="0 1 0" />
  </joint>
  <link
    name="RBW">
    <inertial>
      <origin
        xyz="0.017684275425927 2.77555756156289E-17 2.77555756156289E-17"
        rpy="0 0 0" />
      <mass
        value="0.193585420779862" />
      <inertia
        ixx="0.000253081141332253"
        ixy="-1.77826406212573E-20"
        ixz="1.08676942117992E-20"
        iyy="0.000136818598566517"
        iyz="3.3881317890172E-21"
        izz="0.000136818598566517" />
    </inertial>
    <visual>
      <origin
        xyz="0 0 0"
        rpy="0 0 0" />
      <geometry>
        <mesh
          filename="package://cw2/meshes/RBW.STL" />
      </geometry>
      <material
        name="">
        <color
          rgba="1 1 1 1" />
      </material>
    </visual>
    <collision>
      <origin
        xyz="0 0 0"
        rpy="0 0 0" />
      <geometry>
        <mesh
          filename="package://cw2/meshes/RBW.STL" />
      </geometry>
    </collision>
  </link>
  <joint
    name="RBW"
    type="continuous">
    <origin
      xyz="0.01075 -0.0190326828634147 0"
      rpy="1.78079104161261 0 0" />
    <parent
      link="RBC" />
    <child
      link="RBW" />
    <axis
      xyz="1 0 0" />
  </joint>
  <link
    name="Lidar">
    <inertial>
      <origin
        xyz="-0.0784930223787604 -0.744427430950029 -0.133449677865896"
        rpy="0 0 0" />
      <mass
        value="0.0730845704999828" />
      <inertia
        ixx="1.95808756791187E-05"
        ixy="4.28391210140712E-07"
        ixz="-1.03933581663682E-07"
        iyy="4.14184516311443E-05"
        iyz="-9.42671864204423E-09"
        izz="2.41250079960291E-05" />
    </inertial>
    <visual>
      <origin
        xyz="0 0 0"
        rpy="0 0 0" />
      <geometry>
        <mesh
          filename="package://cw2/meshes/Lidar.STL" />
      </geometry>
      <material
        name="">
        <color
          rgba="0.792156862745098 0.819607843137255 0.933333333333333 1" />
      </material>
    </visual>
    <collision>
      <origin
        xyz="0 0 0"
        rpy="0 0 0" />
      <geometry>
        <mesh
          filename="package://cw2/meshes/Lidar.STL" />
      </geometry>
    </collision>
  </link>
  <joint
    name="Lidar"
    type="fixed">
    <origin
      xyz="0.121678091713213 -0.353083263507212 -0.627184038555925"
      rpy="-1.57079634786832 0 -1.5707963267949" />
    <parent
      link="Base" />
    <child
      link="Lidar" />
    <axis
      xyz="0 0 0" />
  </joint>
  <link
    name="Cam">
    <inertial>
      <origin
        xyz="-0.0238863589328312 -0.0255006330045159 0.0933352730175543"
        rpy="0 0 0" />
      <mass
        value="0.0842240111641082" />
      <inertia
        ixx="1.39666927752748E-05"
        ixy="-8.82405655949378E-10"
        ixz="-1.01133319009129E-09"
        iyy="3.67256443822933E-05"
        iyz="-1.51507686967881E-06"
        izz="3.01150328860415E-05" />
    </inertial>
    <visual>
      <origin
        xyz="0 0 0"
        rpy="0 0 0" />
      <geometry>
        <mesh
          filename="package://cw2/meshes/Cam.STL" />
      </geometry>
      <material
        name="">
        <color
          rgba="0.752941176470588 0.752941176470588 0.752941176470588 1" />
      </material>
    </visual>
    <collision>
      <origin
        xyz="0 0 0"
        rpy="0 0 0" />
      <geometry>
        <mesh
          filename="package://cw2/meshes/Cam.STL" />
      </geometry>
    </collision>
  </link>
  <joint
    name="Cam"
    type="fixed">
    <origin
      xyz="0.0126515628898378 -0.352319258255753 0.0862562798773894"
      rpy="1.71881318872403 0 0" />
    <parent
      link="Base" />
    <child
      link="Cam" />
    <axis
      xyz="0 0 0" />
  </joint>
</robot>